Workbook

Sheet Summary
A1: Residential High-Rise Investment Summary | B1: Residential High-Rise Investment Summary | C1: Residential High-Rise Investment Summary | D1: Residential High-Rise Investment Summary | E1: Residential High-Rise Investment Summary | F1: Residential High-Rise Investment Summary
A4: File Ref. | B4: Illustrative buyer template
A5: Date of Inspection | B5: To be inserted
A6: Date of Valuation | B6: 46220
A7: Purpose of Valuation | B7: Individual investment purchase screening
A8: Property | B8: Sungai Jawi
A9: Type | B9: Residential strata apartment / condominium unit
A10: Address | B10: Penang, Malaysia — replace with subject address
A11: Parcel / Title No. | B11: To be inserted
A12: Floor Area (sf) | B12: 1000
A13: Car Parks | B13: 1
A14: Tenure | B14: Freehold — replace if leasehold
A15: Current Occupancy | B15: Investment unit — replace with tenancy status
A16: Buyer Profile | B16: Individual Malaysian citizen (illustrative tax treatment)
A17: Model Basis | B17: 5-year unlevered DCF plus terminal capitalization; separate levered buyer return
A18: Currency | B18: Malaysian Ringgit (RM)
A20: Key Buyer Outputs | B20: Key Buyer Outputs | C20: Key Buyer Outputs | D20: Key Buyer Outputs | E20: Key Buyer Outputs | F20: Key Buyer Outputs
A21: DCF Value Indication | B21: ='Residential DCF (Buyer)'!$B$69 -> 362439.91 | C21: Purchase Price | D21: ='Residential DCF (Buyer)'!$B$12 -> 450000 | E21: Discount / (Premium) to DCF | F21: =IFERROR((B21-D21)/D21,"") -> -0.19457798
A22: DCF Value per sf | B22: ='Residential DCF (Buyer)'!$B$70 -> 362.43991 | C22: Total Acquisition Cost | D22: ='Residential DCF (Buyer)'!$B$80 -> 501000 | E22: Comparison Indication | F22: =IF('Comparison Approach'!$B$55<>"OK","",'Comparison Approach'!$B$53)
A23: Year 1 NOI | B23: ='Residential DCF (Buyer)'!$F$60 -> 22634.4 | C23: Annual Debt Service | D23: ='Residential DCF (Buyer)'!$B$85 -> 21251.803 | E23: Year 1 DSCR | F23: ='Residential DCF (Buyer)'!$B$86 -> 1.0650579
A24: Equity Required | B24: ='Residential DCF (Buyer)'!$B$83 -> 141000 | C24: Year 1 Cash-on-Cash | D24: ='Residential DCF (Buyer)'!$B$87 -> 0.0098056504 | E24: Levered Equity IRR | F24: ='Residential DCF (Buyer)'!$B$95 -> -0.025486759
A25: Terminal PV / DCF Value | B25: ='Residential DCF (Buyer)'!$B$71 -> 0.74569143 | C25: Minimum DSCR Target | D25: ='Residential DCF (Buyer)'!$E$29 -> 1.1 | E25: Illustrative Hold | F25: ='Residential DCF (Buyer)'!$B$24 -> 5
A27: =IF(AND(B21>=D21,F23>=D25),"PASS SCREEN — validate tenancy, condition and legal due diligence","REVIEW PRICE / RENT / LEVERAGE — illustrative inputs do not meet both value and DSCR screens") -> REVIEW PRICE / RENT / LEVERAGE — illustrative inputs do not meet both value and DSCR screens
A31: Market Value / Purchase Comparison | B31: Market Value / Purchase Comparison | C31: Market Value / Purchase Comparison | D31: Market Value / Purchase Comparison | E31: Market Value / Purchase Comparison | F31: Market Value / Purchase Comparison
A32: Method of Valuation | B32: Value Indication | C32: Variance to Purchase | D32: Purchase Price
A33: Income Approach — Residential DCF (Unlevered) | B33: =B21 -> 362439.91 | C33: =IFERROR((B33-D33)/D33,"") -> -0.19457798 | D33: =D21 -> 450000
A34: Comparison Approach — Adjusted RM/sf | B34: =IF(F22="","",F22) | C34: =IF(B34="","",IFERROR((B34-D34)/D34,"")) | D34: =D21 -> 450000
A35: Cost Approach | B35: Not used for an individual strata unit
A36: Selected Screening Indication | B36: =IF(B34="",B33,AVERAGE(B33,B34)) -> 362439.91 | C36: =IFERROR((B36-D36)/D36,"") -> -0.19457798 | D36: =D21 -> 450000
A39: How to use: replace blue cells with the subject unit's actual purchase price, market rent, JMB/MC charges, insurance, assessment, quit rent, mortgage quote and sale assumptions. DCF value is unlevered; mortgage and buyer tax items are evaluated separately below it. Comparison cells intentionally remain blank until actual verified sale comparables are entered. | B39: How to use: replace blue cells with the subject unit's actual purchase price, market rent, JMB/MC charges, insurance, assessment, quit rent, mortgage quote and sale assumptions. DCF value is unlevered; mortgage and buyer tax items are evaluated separately below it. Comparison cells intentionally remain blank until actual verified sale comparables are entered. | C39: How to use: replace blue cells with the subject unit's actual purchase price, market rent, JMB/MC charges, insurance, assessment, quit rent, mortgage quote and sale assumptions. DCF value is unlevered; mortgage and buyer tax items are evaluated separately below it. Comparison cells intentionally remain blank until actual verified sale comparables are entered. | D39: How to use: replace blue cells with the subject unit's actual purchase price, market rent, JMB/MC charges, insurance, assessment, quit rent, mortgage quote and sale assumptions. DCF value is unlevered; mortgage and buyer tax items are evaluated separately below it. Comparison cells intentionally remain blank until actual verified sale comparables are entered. | E39: How to use: replace blue cells with the subject unit's actual purchase price, market rent, JMB/MC charges, insurance, assessment, quit rent, mortgage quote and sale assumptions. DCF value is unlevered; mortgage and buyer tax items are evaluated separately below it. Comparison cells intentionally remain blank until actual verified sale comparables are entered. | F39: How to use: replace blue cells with the subject unit's actual purchase price, market rent, JMB/MC charges, insurance, assessment, quit rent, mortgage quote and sale assumptions. DCF value is unlevered; mortgage and buyer tax items are evaluated separately below it. Comparison cells intentionally remain blank until actual verified sale comparables are entered.
A40: How to use: replace blue cells with the subject unit's actual purchase price, market rent, JMB/MC charges, insurance, assessment, quit rent, mortgage quote and sale assumptions. DCF value is unlevered; mortgage and buyer tax items are evaluated separately below it. Comparison cells intentionally remain blank until actual verified sale comparables are entered. | B40: How to use: replace blue cells with the subject unit's actual purchase price, market rent, JMB/MC charges, insurance, assessment, quit rent, mortgage quote and sale assumptions. DCF value is unlevered; mortgage and buyer tax items are evaluated separately below it. Comparison cells intentionally remain blank until actual verified sale comparables are entered. | C40: How to use: replace blue cells with the subject unit's actual purchase price, market rent, JMB/MC charges, insurance, assessment, quit rent, mortgage quote and sale assumptions. DCF value is unlevered; mortgage and buyer tax items are evaluated separately below it. Comparison cells intentionally remain blank until actual verified sale comparables are entered. | D40: How to use: replace blue cells with the subject unit's actual purchase price, market rent, JMB/MC charges, insurance, assessment, quit rent, mortgage quote and sale assumptions. DCF value is unlevered; mortgage and buyer tax items are evaluated separately below it. Comparison cells intentionally remain blank until actual verified sale comparables are entered. | E40: How to use: replace blue cells with the subject unit's actual purchase price, market rent, JMB/MC charges, insurance, assessment, quit rent, mortgage quote and sale assumptions. DCF value is unlevered; mortgage and buyer tax items are evaluated separately below it. Comparison cells intentionally remain blank until actual verified sale comparables are entered. | F40: How to use: replace blue cells with the subject unit's actual purchase price, market rent, JMB/MC charges, insurance, assessment, quit rent, mortgage quote and sale assumptions. DCF value is unlevered; mortgage and buyer tax items are evaluated separately below it. Comparison cells intentionally remain blank until actual verified sale comparables are entered.
A41: How to use: replace blue cells with the subject unit's actual purchase price, market rent, JMB/MC charges, insurance, assessment, quit rent, mortgage quote and sale assumptions. DCF value is unlevered; mortgage and buyer tax items are evaluated separately below it. Comparison cells intentionally remain blank until actual verified sale comparables are entered. | B41: How to use: replace blue cells with the subject unit's actual purchase price, market rent, JMB/MC charges, insurance, assessment, quit rent, mortgage quote and sale assumptions. DCF value is unlevered; mortgage and buyer tax items are evaluated separately below it. Comparison cells intentionally remain blank until actual verified sale comparables are entered. | C41: How to use: replace blue cells with the subject unit's actual purchase price, market rent, JMB/MC charges, insurance, assessment, quit rent, mortgage quote and sale assumptions. DCF value is unlevered; mortgage and buyer tax items are evaluated separately below it. Comparison cells intentionally remain blank until actual verified sale comparables are entered. | D41: How to use: replace blue cells with the subject unit's actual purchase price, market rent, JMB/MC charges, insurance, assessment, quit rent, mortgage quote and sale assumptions. DCF value is unlevered; mortgage and buyer tax items are evaluated separately below it. Comparison cells intentionally remain blank until actual verified sale comparables are entered. | E41: How to use: replace blue cells with the subject unit's actual purchase price, market rent, JMB/MC charges, insurance, assessment, quit rent, mortgage quote and sale assumptions. DCF value is unlevered; mortgage and buyer tax items are evaluated separately below it. Comparison cells intentionally remain blank until actual verified sale comparables are entered. | F41: How to use: replace blue cells with the subject unit's actual purchase price, market rent, JMB/MC charges, insurance, assessment, quit rent, mortgage quote and sale assumptions. DCF value is unlevered; mortgage and buyer tax items are evaluated separately below it. Comparison cells intentionally remain blank until actual verified sale comparables are entered.
A42: How to use: replace blue cells with the subject unit's actual purchase price, market rent, JMB/MC charges, insurance, assessment, quit rent, mortgage quote and sale assumptions. DCF value is unlevered; mortgage and buyer tax items are evaluated separately below it. Comparison cells intentionally remain blank until actual verified sale comparables are entered. | B42: How to use: replace blue cells with the subject unit's actual purchase price, market rent, JMB/MC charges, insurance, assessment, quit rent, mortgage quote and sale assumptions. DCF value is unlevered; mortgage and buyer tax items are evaluated separately below it. Comparison cells intentionally remain blank until actual verified sale comparables are entered. | C42: How to use: replace blue cells with the subject unit's actual purchase price, market rent, JMB/MC charges, insurance, assessment, quit rent, mortgage quote and sale assumptions. DCF value is unlevered; mortgage and buyer tax items are evaluated separately below it. Comparison cells intentionally remain blank until actual verified sale comparables are entered. | D42: How to use: replace blue cells with the subject unit's actual purchase price, market rent, JMB/MC charges, insurance, assessment, quit rent, mortgage quote and sale assumptions. DCF value is unlevered; mortgage and buyer tax items are evaluated separately below it. Comparison cells intentionally remain blank until actual verified sale comparables are entered. | E42: How to use: replace blue cells with the subject unit's actual purchase price, market rent, JMB/MC charges, insurance, assessment, quit rent, mortgage quote and sale assumptions. DCF value is unlevered; mortgage and buyer tax items are evaluated separately below it. Comparison cells intentionally remain blank until actual verified sale comparables are entered. | F42: How to use: replace blue cells with the subject unit's actual purchase price, market rent, JMB/MC charges, insurance, assessment, quit rent, mortgage quote and sale assumptions. DCF value is unlevered; mortgage and buyer tax items are evaluated separately below it. Comparison cells intentionally remain blank until actual verified sale comparables are entered.

Sheet Residential DCF (Buyer)
A1: Residential High-Rise DCF — Individual Buyer | B1: Residential High-Rise DCF — Individual Buyer | C1: Residential High-Rise DCF — Individual Buyer | D1: Residential High-Rise DCF — Individual Buyer | E1: Residential High-Rise DCF — Individual Buyer | F1: Residential High-Rise DCF — Individual Buyer | G1: Residential High-Rise DCF — Individual Buyer | H1: Residential High-Rise DCF — Individual Buyer | I1: Residential High-Rise DCF — Individual Buyer | J1: Residential High-Rise DCF — Individual Buyer | K1: Residential High-Rise DCF — Individual Buyer
A3: Subject Property | B3: =Summary!$B$8 -> Sungai Jawi
A4: Property Type | B4: =Summary!$B$9 -> Residential strata apartment / condominium unit
A5: Address | B5: =Summary!$B$10 -> Penang, Malaysia — replace with subject address
A6: Tenure | B6: =Summary!$B$14 -> Freehold — replace if leasehold
A7: Floor Area (sf) | B7: =Summary!$B$12 -> 1000
A8: Car Parks | B8: =Summary!$B$13 -> 1
A9: Valuation Date | B9: =Summary!$B$6 -> 46220
A11: Property & DCF Assumptions | B11: Property & DCF Assumptions | C11: Property & DCF Assumptions | D11: Owner Costs & Financing | E11: Owner Costs & Financing
A12: Purchase price | B12: 450000 | C12: RM | D12: Maintenance/service charge | E12: 0.35
A13: Year 1 monthly market rent | B13: 3000 | C13: RM / month | D13: Sinking fund % of maintenance | E13: 0.1
A14: Other monthly income (parking / storage) | B14: 150 | C14: RM / month | D14: Annual assessment | E14: 700
A15: Year 1 economic occupancy | B15: 0.92 | C15: % | D15: Annual quit rent | E15: 80
A16: Stabilized occupancy | B16: 0.94 | C16: % | D16: Annual unit / landlord insurance | E16: 600
A17: Annual occupancy step | B17: 0.01 | C17: % points | D17: Property management fee | E17: 0.08
A18: Annual rent growth | B18: 0.03 | C18: % | D18: Letting / renewal allowance | E18: 0.04
A19: Annual other-income growth | B19: 0.03 | C19: % | D19: Repairs & maintenance allowance | E19: 0.03
A20: Annual expense inflation | B20: 0.03 | C20: % | D20: Owner-paid utilities / internet | E20: 0
A21: DCF discount rate | B21: 0.1 | C21: % | D21: Furnishing / appliance reserve | E21: 0.02
A22: Terminal capitalization rate | B22: 0.06 | C22: % | D22: Miscellaneous / admin | E22: 0.01
A23: Selling costs | B23: 0.03 | C23: % of sale value | D23: Annual special assessment / capex | E23: 0
... A25: Months per year | B25: 12 | C25: months | D25: Mortgage interest rate | E25: 0.0425
D26: Loan term | E26: 30
D27: Buyer marginal income-tax rate | E27: 0
D28: Illustrative RPGT rate at end-Year 5 | E28: 0.15
D29: Minimum DSCR target | E29: 1.1
D30: MOT stamp duty — solicitor estimate | E30: 9000
D31: Legal / disbursement / due diligence | E31: 8000
D32: Loan / valuation fees | E32: 4000
D33: Initial renovation / furnishing | E33: 25000
D34: Buyer contingency | E34: 5000
D35: Reserved
A37: Projection — Residential Rental Income and Owner-Cost Logic | B37: Projection — Residential Rental Income and Owner-Cost Logic | C37: Projection — Residential Rental Income and Owner-Cost Logic | D37: Projection — Residential Rental Income and Owner-Cost Logic | E37: Projection — Residential Rental Income and Owner-Cost Logic | F37: Projection — Residential Rental Income and Owner-Cost Logic | G37: Projection — Residential Rental Income and Owner-Cost Logic | H37: Projection — Residential Rental Income and Owner-Cost Logic | I37: Projection — Residential Rental Income and Owner-Cost Logic | J37: Projection — Residential Rental Income and Owner-Cost Logic | K37: Projection — Residential Rental Income and Owner-Cost Logic
A38: Cash Flow Item | B38: Basis | C38: Unit | D38: Source / Input | F38: Year 1 | G38: Year 2 | H38: Year 3 | I38: Year 4 | J38: Year 5 | K38: Year 6 / Terminal
A39: Monthly market rent | B39: Prior year × growth | C39: RM / month | D39: Buyer rent comparables | F39: =$B$13 -> 3000 | G39: =F39*(1+$B$18) -> 3090 | H39: =G39*(1+$B$18) -> 3182.7 | I39: =H39*(1+$B$18) -> 3278.181 | J39: =I39*(1+$B$18) -> 3376.5264 | K39: =J39*(1+$B$18) -> 3477.8222
A40: Gross potential rent | B40: Monthly rent × months | C40: RM / year | D40: Formula | F40: =F39*$B$25 -> 36000 | G40: =G39*$B$25 -> 37080 | H40: =H39*$B$25 -> 38192.4 | I40: =I39*$B$25 -> 39338.172 | J40: =J39*$B$25 -> 40518.317 | K40: =K39*$B$25 -> 41733.867
A41: Economic occupancy | B41: Ramp to stabilized rate | C41: % | D41: Buyer assumption | F41: =MIN($B$16,$B$15+(0)*$B$17) -> 0.92 | G41: =MIN($B$16,$B$15+(1)*$B$17) -> 0.93 | H41: =MIN($B$16,$B$15+(2)*$B$17) -> 0.94 | I41: =MIN($B$16,$B$15+(3)*$B$17) -> 0.94 | J41: =MIN($B$16,$B$15+(4)*$B$17) -> 0.94 | K41: =MIN($B$16,$B$15+(5)*$B$17) -> 0.94
A42: Vacancy & credit loss | B42: GPR × (1 − occupancy) | C42: RM / year | D42: Formula | F42: =-F40*(1-F41) -> -2880 | G42: =-G40*(1-G41) -> -2595.6 | H42: =-H40*(1-H41) -> -2291.544 | I42: =-I40*(1-I41) -> -2360.2903 | J42: =-J40*(1-J41) -> -2431.099 | K42: =-K40*(1-K41) -> -2504.032
A43: Other income | B43: Parking / storage | C43: RM / year | D43: Buyer assumption | F43: =$B$14*$B$25 -> 1800 | G43: =F43*(1+$B$19) -> 1854 | H43: =G43*(1+$B$19) -> 1909.62 | I43: =H43*(1+$B$19) -> 1966.9086 | J43: =I43*(1+$B$19) -> 2025.9159 | K43: =J43*(1+$B$19) -> 2086.6933
A44: (A) EFFECTIVE GROSS INCOME | B44: Rent less vacancy plus other income | C44: RM / year | D44: Formula | F44: =SUM(F40,F42:F43) -> 34920 | G44: =SUM(G40,G42:G43) -> 36338.4 | H44: =SUM(H40,H42:H43) -> 37810.476 | I44: =SUM(I40,I42:I43) -> 38944.79 | J44: =SUM(J40,J42:J43) -> 40113.134 | K44: =SUM(K40,K42:K43) -> 41316.528
...

Sheet Comparison Approach
A1: Comparison Approach — Residential High-Rise Unit | B1: Comparison Approach — Residential High-Rise Unit | C1: Comparison Approach — Residential High-Rise Unit | D1: Comparison Approach — Residential High-Rise Unit | E1: Comparison Approach — Residential High-Rise Unit | F1: Comparison Approach — Residential High-Rise Unit
A3: Property | B3: =Summary!$B$8 -> Sungai Jawi
A4: Property Type | B4: =Summary!$B$9 -> Residential strata apartment / condominium unit
A5: Address | B5: =Summary!$B$10 -> Penang, Malaysia — replace with subject address
A6: Tenure | B6: =Summary!$B$14 -> Freehold — replace if leasehold
A7: Floor Area (sf) | B7: =Summary!$B$12 -> 1000
A8: Car Parks | B8: =Summary!$B$13 -> 1
A9: DCF Value | B9: ='Residential DCF (Buyer)'!$B$69 -> 362439.91
A10: DCF Value per sf | B10: ='Residential DCF (Buyer)'!$B$70 -> 362.43991
A11: Valuation Date | B11: =Summary!$B$6 -> 46220
A12: Comparable Evidence Status | B12: Enter at least three verified transactions
A15: Comparable Sales — Enter Verified Transactions | B15: Comparable Sales — Enter Verified Transactions | C15: Comparable Sales — Enter Verified Transactions | D15: Comparable Sales — Enter Verified Transactions | E15: Comparable Sales — Enter Verified Transactions | F15: Comparable Sales — Enter Verified Transactions
A16: Comparable Item | B16: Subject Property | C16: Comparable 1 | D16: Comparable 2 | E16: Comparable 3 | F16: Comparable 4
A17: Source / URL | B17: Subject documents
A18: Project / Building | B18: =Summary!$B$8 -> Sungai Jawi
A19: Address / Location | B19: =Summary!$B$10 -> Penang, Malaysia — replace with subject address
A20: Transaction Date | B20: =Summary!$B$6 -> 46220
A21: Sale Price
A22: Floor Area (sf) | B22: =Summary!$B$13 -> 1
A23: Raw RM per sf | C23: =IFERROR(C21/C22,"") | D23: =IFERROR(D21/D22,"") | E23: =IFERROR(E21/E22,"") | F23: =IFERROR(F21/F22,"")
A24: Floor / View | B24: To be inspected
A25: Condition / Renovation | B25: To be inspected
A26: Car Parks | B26: =Summary!$B$13 -> 1
A27: Tenure / Remaining Term | B27: =Summary!$B$14 -> Freehold — replace if leasehold
A28: Maintenance Charge (RM/psf/month) | B28: ='Residential DCF (Buyer)'!$E$12 -> 0.35
A30: Adjustments to Comparable RM per sf | B30: Adjustments to Comparable RM per sf | C30: Adjustments to Comparable RM per sf | D30: Adjustments to Comparable RM per sf | E30: Adjustments to Comparable RM per sf | F30: Adjustments to Comparable RM per sf
A31: Adjustment Item | B31: Subject Property | C31: Comparable 1 | D31: Comparable 2 | E31: Comparable 3 | F31: Comparable 4
A32: Time / Market Conditions | B32: Benchmark
A33: Location & Accessibility | B33: Benchmark
A34: Building Age / Condition | B34: Benchmark
A35: Floor Level / View / Orientation | B35: Benchmark
A36: Unit Size / Layout Efficiency | B36: Benchmark
A37: Facilities / Management Quality | B37: Benchmark
A38: Car Park Entitlement | B38: Benchmark
A39: Tenure / Remaining Lease | B39: Benchmark
A40: Condition / Furnishing | B40: Benchmark
A41: Maintenance Burden | B41: Benchmark
A42: TOTAL ADJUSTMENT | C42: =SUM(C32:C41) -> 0 | D42: =SUM(D32:D41) -> 0 | E42: =SUM(E32:E41) -> 0 | F42: =SUM(F32:F41) -> 0
A43: Adjusted RM per sf | C43: =IFERROR(C23*(1+C42),"") | D43: =IFERROR(D23*(1+D42),"") | E43: =IFERROR(E23*(1+E42),"") | F43: =IFERROR(F23*(1+F42),"")
A45: Comparable Included? | C45: =IF(C43="","No","Yes") -> No | D45: =IF(D43="","No","Yes") -> No | E45: =IF(E43="","No","Yes") -> No | F45: =IF(F43="","No","Yes") -> No
...

Sheet Sources & Guidance
A1: Residential High-Rise DCF — Sources, Translation Map & Checks | B1: Residential High-Rise DCF — Sources, Translation Map & Checks | C1: Residential High-Rise DCF — Sources, Translation Map & Checks | D1: Residential High-Rise DCF — Sources, Translation Map & Checks | E1: Residential High-Rise DCF — Sources, Translation Map & Checks | F1: Residential High-Rise DCF — Sources, Translation Map & Checks
A3: This workbook adapts the Holiday Inn hotel profit-method template into an individual buyer model for one residential high-rise unit. The core linkage remains income → owner operating expenses → NOI → discounted forecast NOI → terminal value. Financing and personal tax are shown separately because they affect the buyer's equity return, not the unlevered property value. | B3: This workbook adapts the Holiday Inn hotel profit-method template into an individual buyer model for one residential high-rise unit. The core linkage remains income → owner operating expenses → NOI → discounted forecast NOI → terminal value. Financing and personal tax are shown separately because they affect the buyer's equity return, not the unlevered property value. | C3: This workbook adapts the Holiday Inn hotel profit-method template into an individual buyer model for one residential high-rise unit. The core linkage remains income → owner operating expenses → NOI → discounted forecast NOI → terminal value. Financing and personal tax are shown separately because they affect the buyer's equity return, not the unlevered property value. | D3: This workbook adapts the Holiday Inn hotel profit-method template into an individual buyer model for one residential high-rise unit. The core linkage remains income → owner operating expenses → NOI → discounted forecast NOI → terminal value. Financing and personal tax are shown separately because they affect the buyer's equity return, not the unlevered property value. | E3: This workbook adapts the Holiday Inn hotel profit-method template into an individual buyer model for one residential high-rise unit. The core linkage remains income → owner operating expenses → NOI → discounted forecast NOI → terminal value. Financing and personal tax are shown separately because they affect the buyer's equity return, not the unlevered property value. | F3: This workbook adapts the Holiday Inn hotel profit-method template into an individual buyer model for one residential high-rise unit. The core linkage remains income → owner operating expenses → NOI → discounted forecast NOI → terminal value. Financing and personal tax are shown separately because they affect the buyer's equity return, not the unlevered property value.
A4: This workbook adapts the Holiday Inn hotel profit-method template into an individual buyer model for one residential high-rise unit. The core linkage remains income → owner operating expenses → NOI → discounted forecast NOI → terminal value. Financing and personal tax are shown separately because they affect the buyer's equity return, not the unlevered property value. | B4: This workbook adapts the Holiday Inn hotel profit-method template into an individual buyer model for one residential high-rise unit. The core linkage remains income → owner operating expenses → NOI → discounted forecast NOI → terminal value. Financing and personal tax are shown separately because they affect the buyer's equity return, not the unlevered property value. | C4: This workbook adapts the Holiday Inn hotel profit-method template into an individual buyer model for one residential high-rise unit. The core linkage remains income → owner operating expenses → NOI → discounted forecast NOI → terminal value. Financing and personal tax are shown separately because they affect the buyer's equity return, not the unlevered property value. | D4: This workbook adapts the Holiday Inn hotel profit-method template into an individual buyer model for one residential high-rise unit. The core linkage remains income → owner operating expenses → NOI → discounted forecast NOI → terminal value. Financing and personal tax are shown separately because they affect the buyer's equity return, not the unlevered property value. | E4: This workbook adapts the Holiday Inn hotel profit-method template into an individual buyer model for one residential high-rise unit. The core linkage remains income → owner operating expenses → NOI → discounted forecast NOI → terminal value. Financing and personal tax are shown separately because they affect the buyer's equity return, not the unlevered property value. | F4: This workbook adapts the Holiday Inn hotel profit-method template into an individual buyer model for one residential high-rise unit. The core linkage remains income → owner operating expenses → NOI → discounted forecast NOI → terminal value. Financing and personal tax are shown separately because they affect the buyer's equity return, not the unlevered property value.
A5: This workbook adapts the Holiday Inn hotel profit-method template into an individual buyer model for one residential high-rise unit. The core linkage remains income → owner operating expenses → NOI → discounted forecast NOI → terminal value. Financing and personal tax are shown separately because they affect the buyer's equity return, not the unlevered property value. | B5: This workbook adapts the Holiday Inn hotel profit-method template into an individual buyer model for one residential high-rise unit. The core linkage remains income → owner operating expenses → NOI → discounted forecast NOI → terminal value. Financing and personal tax are shown separately because they affect the buyer's equity return, not the unlevered property value. | C5: This workbook adapts the Holiday Inn hotel profit-method template into an individual buyer model for one residential high-rise unit. The core linkage remains income → owner operating expenses → NOI → discounted forecast NOI → terminal value. Financing and personal tax are shown separately because they affect the buyer's equity return, not the unlevered property value. | D5: This workbook adapts the Holiday Inn hotel profit-method template into an individual buyer model for one residential high-rise unit. The core linkage remains income → owner operating expenses → NOI → discounted forecast NOI → terminal value. Financing and personal tax are shown separately because they affect the buyer's equity return, not the unlevered property value. | E5: This workbook adapts the Holiday Inn hotel profit-method template into an individual buyer model for one residential high-rise unit. The core linkage remains income → owner operating expenses → NOI → discounted forecast NOI → terminal value. Financing and personal tax are shown separately because they affect the buyer's equity return, not the unlevered property value. | F5: This workbook adapts the Holiday Inn hotel profit-method template into an individual buyer model for one residential high-rise unit. The core linkage remains income → owner operating expenses → NOI → discounted forecast NOI → terminal value. Financing and personal tax are shown separately because they affect the buyer's equity return, not the unlevered property value.
A6: This workbook adapts the Holiday Inn hotel profit-method template into an individual buyer model for one residential high-rise unit. The core linkage remains income → owner operating expenses → NOI → discounted forecast NOI → terminal value. Financing and personal tax are shown separately because they affect the buyer's equity return, not the unlevered property value. | B6: This workbook adapts the Holiday Inn hotel profit-method template into an individual buyer model for one residential high-rise unit. The core linkage remains income → owner operating expenses → NOI → discounted forecast NOI → terminal value. Financing and personal tax are shown separately because they affect the buyer's equity return, not the unlevered property value. | C6: This workbook adapts the Holiday Inn hotel profit-method template into an individual buyer model for one residential high-rise unit. The core linkage remains income → owner operating expenses → NOI → discounted forecast NOI → terminal value. Financing and personal tax are shown separately because they affect the buyer's equity return, not the unlevered property value. | D6: This workbook adapts the Holiday Inn hotel profit-method template into an individual buyer model for one residential high-rise unit. The core linkage remains income → owner operating expenses → NOI → discounted forecast NOI → terminal value. Financing and personal tax are shown separately because they affect the buyer's equity return, not the unlevered property value. | E6: This workbook adapts the Holiday Inn hotel profit-method template into an individual buyer model for one residential high-rise unit. The core linkage remains income → owner operating expenses → NOI → discounted forecast NOI → terminal value. Financing and personal tax are shown separately because they affect the buyer's equity return, not the unlevered property value. | F6: This workbook adapts the Holiday Inn hotel profit-method template into an individual buyer model for one residential high-rise unit. The core linkage remains income → owner operating expenses → NOI → discounted forecast NOI → terminal value. Financing and personal tax are shown separately because they affect the buyer's equity return, not the unlevered property value.
A8: Hotel-to-Residential Translation Map | B8: Hotel-to-Residential Translation Map | C8: Hotel-to-Residential Translation Map | D8: Hotel-to-Residential Translation Map | E8: Hotel-to-Residential Translation Map | F8: Hotel-to-Residential Translation Map
A9: Original Hotel Item | B9: Residential Replacement | C9: Keep / Remove / Add | D9: Formula Treatment | E9: Why It Matters | F9: Where Used
A10: Total rooms | B10: One subject strata unit | C10: Change | D10: Unit count becomes 1; floor area drives value per sf and charges | E10: An individual buys one parcel, not a hotel room inventory | F10: Summary / DCF
A11: Average room rate (ARR) | B11: Monthly market rent | C11: Change | D11: Monthly rent × 12 | E11: Primary recurring income driver | F11: DCF rows 39–40
A12: Occupancy rate | B12: Economic occupancy | C12: Change | D12: GPR × occupancy; vacancy shown separately | E12: Captures vacancy and credit loss | F12: DCF rows 41–42
A13: RevPAR | B13: Effective rent after vacancy | C13: Change | D13: Gross rent less vacancy | E13: Residential equivalent of utilized room income | F13: DCF row 44
A14: Food & beverage revenue | B14: Remove | C14: Remove | D14: No formula | E14: Not earned by a single unit owner | F14: Not used
... A47: Check | B47: Actual | C47: Expected | D47: Difference / Count | E47: Status | F47: Fix Hint
A48: DCF indication is positive | B48: ='Residential DCF (Buyer)'!$B$69 -> 362439.91 | C48: > 0 | D48: =B48 -> 362439.91 | E48: =IF(B48>0,"OK","REVIEW") -> OK | F48: Review rent, vacancy, expenses and terminal cap
A49: Discount rate exceeds terminal cap rate | B49: ='Residential DCF (Buyer)'!$B$21 -> 0.1 | C49: ='Residential DCF (Buyer)'!$B$22 -> 0.06 | D49: =B49-C49 -> 0.04 | E49: =IF(B49>C49,"OK","REVIEW") -> OK | F49: Review long-term growth and risk assumptions
A50: Terminal PV concentration | B50: ='Residential DCF (Buyer)'!$B$71 -> 0.74569143 | C50: 0.8 | D50: =B50-C50 -> -0.054308568 | E50: =IF(B50<=C50,"OK","REVIEW") -> OK | F50: Long-term value is too dominant; stress terminal cap
A51: Year 1 DSCR | B51: ='Residential DCF (Buyer)'!$B$86 -> 1.0650579 | C51: ='Residential DCF (Buyer)'!$E$29 -> 1.1 | D51: =B51-C51 -> -0.034942146 | E51: =IF(B51>=C51,"OK","REVIEW") -> REVIEW | F51: Reduce leverage / price or improve sustainable NOI
A52: Comparable sale count | B52: =COUNT('Comparison Approach'!$C$21:$F$21) -> 0 | C52: ≥ 3 | D52: =B52-3 -> -3 | E52: =IF(B52>=3,"OK","INPUT NEEDED") -> INPUT NEEDED | F52: Enter verified completed transactions
A53: Purchase price vs DCF | B53: ='Residential DCF (Buyer)'!$B$12 -> 450000 | C53: ='Residential DCF (Buyer)'!$B$69 -> 362439.91 | D53: =C53-B53 -> -87560.092 | E53: =IF(B53<=C53,"OK","REVIEW") -> REVIEW | F53: Review price, rent and required return
A54: OVERALL SCREEN | C54: All core checks OK | E54: =IF(AND(E48="OK",E49="OK",E50="OK",E51="OK",E53="OK"),"CORE MODEL OK — COMPLETE COMPARABLES","REVIEW CORE ASSUMPTIONS") -> REVIEW CORE ASSUMPTIONS | F54: Resolve REVIEW / INPUT NEEDED items before relying on output
A57: Important: this is an illustrative decision-support template, not a valuation report, investment recommendation, mortgage offer, legal opinion or tax computation. Market rent, comparables, strata liabilities, title restrictions, special assessments, financing terms and taxes must be verified for the actual unit and buyer. | B57: Important: this is an illustrative decision-support template, not a valuation report, investment recommendation, mortgage offer, legal opinion or tax computation. Market rent, comparables, strata liabilities, title restrictions, special assessments, financing terms and taxes must be verified for the actual unit and buyer. | C57: Important: this is an illustrative decision-support template, not a valuation report, investment recommendation, mortgage offer, legal opinion or tax computation. Market rent, comparables, strata liabilities, title restrictions, special assessments, financing terms and taxes must be verified for the actual unit and buyer. | D57: Important: this is an illustrative decision-support template, not a valuation report, investment recommendation, mortgage offer, legal opinion or tax computation. Market rent, comparables, strata liabilities, title restrictions, special assessments, financing terms and taxes must be verified for the actual unit and buyer. | E57: Important: this is an illustrative decision-support template, not a valuation report, investment recommendation, mortgage offer, legal opinion or tax computation. Market rent, comparables, strata liabilities, title restrictions, special assessments, financing terms and taxes must be verified for the actual unit and buyer. | F57: Important: this is an illustrative decision-support template, not a valuation report, investment recommendation, mortgage offer, legal opinion or tax computation. Market rent, comparables, strata liabilities, title restrictions, special assessments, financing terms and taxes must be verified for the actual unit and buyer.
A58: Important: this is an illustrative decision-support template, not a valuation report, investment recommendation, mortgage offer, legal opinion or tax computation. Market rent, comparables, strata liabilities, title restrictions, special assessments, financing terms and taxes must be verified for the actual unit and buyer. | B58: Important: this is an illustrative decision-support template, not a valuation report, investment recommendation, mortgage offer, legal opinion or tax computation. Market rent, comparables, strata liabilities, title restrictions, special assessments, financing terms and taxes must be verified for the actual unit and buyer. | C58: Important: this is an illustrative decision-support template, not a valuation report, investment recommendation, mortgage offer, legal opinion or tax computation. Market rent, comparables, strata liabilities, title restrictions, special assessments, financing terms and taxes must be verified for the actual unit and buyer. | D58: Important: this is an illustrative decision-support template, not a valuation report, investment recommendation, mortgage offer, legal opinion or tax computation. Market rent, comparables, strata liabilities, title restrictions, special assessments, financing terms and taxes must be verified for the actual unit and buyer. | E58: Important: this is an illustrative decision-support template, not a valuation report, investment recommendation, mortgage offer, legal opinion or tax computation. Market rent, comparables, strata liabilities, title restrictions, special assessments, financing terms and taxes must be verified for the actual unit and buyer. | F58: Important: this is an illustrative decision-support template, not a valuation report, investment recommendation, mortgage offer, legal opinion or tax computation. Market rent, comparables, strata liabilities, title restrictions, special assessments, financing terms and taxes must be verified for the actual unit and buyer.
A59: Important: this is an illustrative decision-support template, not a valuation report, investment recommendation, mortgage offer, legal opinion or tax computation. Market rent, comparables, strata liabilities, title restrictions, special assessments, financing terms and taxes must be verified for the actual unit and buyer. | B59: Important: this is an illustrative decision-support template, not a valuation report, investment recommendation, mortgage offer, legal opinion or tax computation. Market rent, comparables, strata liabilities, title restrictions, special assessments, financing terms and taxes must be verified for the actual unit and buyer. | C59: Important: this is an illustrative decision-support template, not a valuation report, investment recommendation, mortgage offer, legal opinion or tax computation. Market rent, comparables, strata liabilities, title restrictions, special assessments, financing terms and taxes must be verified for the actual unit and buyer. | D59: Important: this is an illustrative decision-support template, not a valuation report, investment recommendation, mortgage offer, legal opinion or tax computation. Market rent, comparables, strata liabilities, title restrictions, special assessments, financing terms and taxes must be verified for the actual unit and buyer. | E59: Important: this is an illustrative decision-support template, not a valuation report, investment recommendation, mortgage offer, legal opinion or tax computation. Market rent, comparables, strata liabilities, title restrictions, special assessments, financing terms and taxes must be verified for the actual unit and buyer. | F59: Important: this is an illustrative decision-support template, not a valuation report, investment recommendation, mortgage offer, legal opinion or tax computation. Market rent, comparables, strata liabilities, title restrictions, special assessments, financing terms and taxes must be verified for the actual unit and buyer.
A60: Important: this is an illustrative decision-support template, not a valuation report, investment recommendation, mortgage offer, legal opinion or tax computation. Market rent, comparables, strata liabilities, title restrictions, special assessments, financing terms and taxes must be verified for the actual unit and buyer. | B60: Important: this is an illustrative decision-support template, not a valuation report, investment recommendation, mortgage offer, legal opinion or tax computation. Market rent, comparables, strata liabilities, title restrictions, special assessments, financing terms and taxes must be verified for the actual unit and buyer. | C60: Important: this is an illustrative decision-support template, not a valuation report, investment recommendation, mortgage offer, legal opinion or tax computation. Market rent, comparables, strata liabilities, title restrictions, special assessments, financing terms and taxes must be verified for the actual unit and buyer. | D60: Important: this is an illustrative decision-support template, not a valuation report, investment recommendation, mortgage offer, legal opinion or tax computation. Market rent, comparables, strata liabilities, title restrictions, special assessments, financing terms and taxes must be verified for the actual unit and buyer. | E60: Important: this is an illustrative decision-support template, not a valuation report, investment recommendation, mortgage offer, legal opinion or tax computation. Market rent, comparables, strata liabilities, title restrictions, special assessments, financing terms and taxes must be verified for the actual unit and buyer. | F60: Important: this is an illustrative decision-support template, not a valuation report, investment recommendation, mortgage offer, legal opinion or tax computation. Market rent, comparables, strata liabilities, title restrictions, special assessments, financing terms and taxes must be verified for the actual unit and buyer.
